<!-- // The Ch11_pgm_03 promise has been settled with resolve. Let us another example when the promise is settled with reject.

// Promise
const doPromise = new Promise((resolve, reject) => {
    setTimeout(() => {
      const skills = ['HTML', 'CSS', 'JS']
      if (skills.includes('Node')) {
        resolve('fullstack developer')
      } else {
        reject('Something wrong has happened')
      }
    }, 2000)
  })
  
  doPromise
    .then(result => {
      console.log(result)
    })
    .catch(error => console.error(error))



    // Something wrong has happened -->
<html lang="en">
    <head>
       <meta charset="UTF-8">
       <meta name="viewport" content="width=device-width, initial-scale=1.0">
       <title>Ch11</title>
    </head>
    <body>
       <script> 
const doPromise = new Promise((resolve, reject) => {
  setTimeout(() => {
    const skills = ['HTML', 'CSS', 'JS']
    console.log('Checking skills:', skills); // Debugging line
    if (skills.includes('Node')) {
      resolve('fullstack developer')
    } else {
      reject('Something wrong has happened')
    }
  }, 2000)
})

doPromise
  .then(result => {
    console.log('Promise resolved with result:', result); // Debugging line
  })
  .catch(error => console.error('Promise rejected with error:', error)) // Debugging line

</script>
</body>
</html>  